Workbook
Name Slicer_Diabetes_Status: #N/A
Name Slicer_Weight_Status: #N/A

Sheet Customer Names
A1: Customer ID | B1: Name | C1: Title | D1: First Name | E1: Last Name
A2: Id1 | B2: Hawks, Ms. Kelly | C2: Ms | D2: Kelly | E2: Hawks
A3: Id2 | B3: Lehner, Mr. Matthew D | C3: Mr | D3: Matthew D | E3: Lehner
A4: Id3 | B4: Lu, Mr. Phil | C4: Mr | D4: Phil | E4: Lu
A5: Id4 | B5: Osborne, Ms. Kelsey | C5: Ms | D5: Kelsey | E5: Osborne
A6: Id5 | B6: Kadala, Ms. Kristyn | C6: Ms | D6: Kristyn | E6: Kadala
A7: Id6 | B7: Baker, Mr. Russell B. | C7: Mr | D7: Russell B | E7: Baker
A8: Id7 | B8: Macpherson, Mr. Scott | C8: Mr | D8: Scott | E8: Macpherson
A9: Id8 | B9: Hallman, Mr. Stephen | C9: Mr | D9: Stephen | E9: Hallman
A10: Id9 | B10: Moran, Mr. Patrick R. | C10: Mr | D10: Patrick R | E10: Moran
A11: Id10 | B11: Benner, Ms. Brooke N. | C11: Ms | D11: Brooke N | E11: Benner
A12: Id11 | B12: Fierro Vargas, Ms. Paola Andrea | C12: Ms | D12: Paola Andrea | E12: Fierro Vargas
... A2336: Id2335 | B2336: German, Mr. Aaron K | C2336: Mr | D2336: Aaron K | E2336: German

Sheet Medical Examination
A1: Customer ID | B1: BMI | C1: HBA1C | D1: Heart Issues | E1: Any Transplants | F1: Cancer History | G1: Number Of Major Surgeries | H1: Smoker | I1: Weight Status | J1: Diabetes Status
A2: Id1 | B2: 47.41 | C2: 7.47 | D2: No | E2: No | F2: No | G2: 0 | H2: Smoker | I2: =IF(B2<18.5,"Under Weight",IF(B2<24.9,"Normal Weight",IF(B2<29.9,"Over Weight","Obesity"))) -> Obesity | J2: =IF(C3<5.7,"Normal",IF(C3<6.4,"Prediabetes","Diabetes")) -> Prediabetes
A3: Id2 | B3: 30.36 | C3: 5.77 | D3: No | E3: No | F3: No | G3: 0 | H3: Smoker | I3: =IF(B3<18.5,"Under Weight",IF(B3<24.9,"Normal Weight",IF(B3<29.9,"Over Weight","Obesity"))) -> Obesity | J3: =IF(C4<5.7,"Normal",IF(C4<6.4,"Prediabetes","Diabetes")) -> Diabetes
A4: Id3 | B4: 34.485 | C4: 11.87 | D4: Yes | E4: No | F4: No | G4: 2 | H4: Smoker | I4: =IF(B4<18.5,"Under Weight",IF(B4<24.9,"Normal Weight",IF(B4<29.9,"Over Weight","Obesity"))) -> Obesity | J4: =IF(C5<5.7,"Normal",IF(C5<6.4,"Prediabetes","Diabetes")) -> Prediabetes
A5: Id4 | B5: 38.095 | C5: 6.05 | D5: No | E5: No | F5: No | G5: 0 | H5: Smoker | I5: =IF(B5<18.5,"Under Weight",IF(B5<24.9,"Normal Weight",IF(B5<29.9,"Over Weight","Obesity"))) -> Obesity | J5: =IF(C6<5.7,"Normal",IF(C6<6.4,"Prediabetes","Diabetes")) -> Normal
A6: Id5 | B6: 35.53 | C6: 5.45 | D6: No | E6: No | F6: No | G6: 0 | H6: Smoker | I6: =IF(B6<18.5,"Under Weight",IF(B6<24.9,"Normal Weight",IF(B6<29.9,"Over Weight","Obesity"))) -> Obesity | J6: =IF(C7<5.7,"Normal",IF(C7<6.4,"Prediabetes","Diabetes")) -> Diabetes
A7: Id6 | B7: 32.8 | C7: 6.59 | D7: No | E7: No | F7: No | G7: 0 | H7: Smoker | I7: =IF(B7<18.5,"Under Weight",IF(B7<24.9,"Normal Weight",IF(B7<29.9,"Over Weight","Obesity"))) -> Obesity | J7: =IF(C8<5.7,"Normal",IF(C8<6.4,"Prediabetes","Diabetes")) -> Prediabetes
A8: Id7 | B8: 36.4 | C8: 6.07 | D8: No | E8: No | F8: No | G8: 0 | H8: Smoker | I8: =IF(B8<18.5,"Under Weight",IF(B8<24.9,"Normal Weight",IF(B8<29.9,"Over Weight","Obesity"))) -> Obesity | J8: =IF(C9<5.7,"Normal",IF(C9<6.4,"Prediabetes","Diabetes")) -> Diabetes
A9: Id8 | B9: 36.96 | C9: 7.93 | D9: No | E9: No | F9: No | G9: 3 | H9: Smoker | I9: =IF(B9<18.5,"Under Weight",IF(B9<24.9,"Normal Weight",IF(B9<29.9,"Over Weight","Obesity"))) -> Obesity | J9: =IF(C10<5.7,"Normal",IF(C10<6.4,"Prediabetes","Diabetes")) -> Diabetes
A10: Id9 | B10: 41.14 | C10: 9.58 | D10: Yes | E10: No | F10: Yes | G10: 1 | H10: Smoker | I10: =IF(B10<18.5,"Under Weight",IF(B10<24.9,"Normal Weight",IF(B10<29.9,"Over Weight","Obesity"))) -> Obesity | J10: =IF(C11<5.7,"Normal",IF(C11<6.4,"Prediabetes","Diabetes")) -> Diabetes
A11: Id10 | B11: 38.06 | C11: 10.79 | D11: No | E11: No | F11: No | G11: 0 | H11: Smoker | I11: =IF(B11<18.5,"Under Weight",IF(B11<24.9,"Normal Weight",IF(B11<29.9,"Over Weight","Obesity"))) -> Obesity | J11: =IF(C12<5.7,"Normal",IF(C12<6.4,"Prediabetes","Diabetes")) -> Prediabetes
A12: Id11 | B12: 37.7 | C12: 5.96 | D12: Yes | E12: No | F12: No | G12: 2 | H12: Smoker | I12: =IF(B12<18.5,"Under Weight",IF(B12<24.9,"Normal Weight",IF(B12<29.9,"Over Weight","Obesity"))) -> Obesity | J12: =IF(C13<5.7,"Normal",IF(C13<6.4,"Prediabetes","Diabetes")) -> Diabetes
A13: Id12 | B13: 42.13 | C13: 11.9 | D13: No | E13: No | F13: No | G13: 0 | H13: Smoker | I13: =IF(B13<18.5,"Under Weight",IF(B13<24.9,"Normal Weight",IF(B13<29.9,"Over Weight","Obesity"))) -> Obesity | J13: =IF(C14<5.7,"Normal",IF(C14<6.4,"Prediabetes","Diabetes")) -> Diabetes
... A2336: Id2335 | B2336: 17.58 | C2336: 4.51 | D2336: No | E2336: No | F2336: No | G2336: 1 | H2336: Non Smoker | I2336: =IF(B2336<18.5,"Under Weight",IF(B2336<24.9,"Normal Weight",IF(B2336<29.9,"Over Weight","Obesity"))) -> Under Weight | J2336: =IF(C2337<5.7,"Normal",IF(C2337<6.4,"Prediabetes","Diabetes")) -> Normal

Sheet Hospitalsation Details
A1: Customer ID | B1: Year | C1: Month | D1: Date | E1: Children | F1: Charges | G1: Hospital Tier | H1: City Tier | I1: State ID | J1: Date Of Birth | K1: Date Of Collection Dataset | L1: Age
A2: Id1 | B2: 1968 | C2: Oct | D2: 12 | E2: 0 | F2: 63770.43 | G2: tier - 1 | H2: tier - 3 | I2: R1013 | J2: =TEXT(DATE(B2,MONTH(1&C2),D2),"dd-mm-yyyy") -> 12-10-1968 | K2: 45085 | L2: =DATEDIF(J2,K2,"Y") -> 54
A3: Id10 | B3: 1978 | C3: Dec | D3: 29 | E3: 0 | F3: 48885.14 | G3: tier - 1 | H3: tier - 2 | I3: R1013 | J3: =TEXT(DATE(B3,MONTH(1&C3),D3),"dd-mm-yyyy") -> 29-12-1978 | K3: 45085 | L3: =DATEDIF(J3,K3,"Y") -> 44
A4: Id100 | B4: 1977 | C4: Jun | D4: 27 | E4: 2 | F4: 40284.38 | G4: tier - 1 | H4: tier - 3 | I4: R1012 | J4: =TEXT(DATE(B4,MONTH(1&C4),D4),"dd-mm-yyyy") -> 27-06-1977 | K4: 45085 | L4: =DATEDIF(J4,K4,"Y") -> 45
A5: Id1000 | B5: 1989 | C5: Dec | D5: 17 | E5: 3 | F5: 11250.43 | G5: tier - 3 | H5: tier - 2 | I5: R1026 | J5: =TEXT(DATE(B5,MONTH(1&C5),D5),"dd-mm-yyyy") -> 17-12-1989 | K5: 45085 | L5: =DATEDIF(J5,K5,"Y") -> 33
A6: Id1001 | B6: 1969 | C6: Dec | D6: 30 | E6: 2 | F6: 11244.38 | G6: tier - 3 | H6: tier - 1 | I6: R1016 | J6: =TEXT(DATE(B6,MONTH(1&C6),D6),"dd-mm-yyyy") -> 30-12-1969 | K6: 45085 | L6: =DATEDIF(J6,K6,"Y") -> 53
A7: Id1002 | B7: 1976 | C7: Jun | D7: 28 | E7: 2 | F7: 11217.35 | G7: tier - 3 | H7: tier - 2 | I7: R1025 | J7: =TEXT(DATE(B7,MONTH(1&C7),D7),"dd-mm-yyyy") -> 28-06-1976 | K7: 45085 | L7: =DATEDIF(J7,K7,"Y") -> 46
A8: Id1003 | B8: 1970 | C8: Jun | D8: 14 | E8: 2 | F8: 11187.66 | G8: tier - 3 | H8: tier - 2 | I8: R1012 | J8: =TEXT(DATE(B8,MONTH(1&C8),D8),"dd-mm-yyyy") -> 14-06-1970 | K8: 45085 | L8: =DATEDIF(J8,K8,"Y") -> 52
A9: Id1004 | B9: 1972 | C9: Sep | D9: 3 | E9: 0 | F9: 11186.2 | G9: tier - 3 | H9: tier - 2 | I9: R1021 | J9: =TEXT(DATE(B9,MONTH(1&C9),D9),"dd-mm-yyyy") -> 03-09-1972 | K9: 45085 | L9: =DATEDIF(J9,K9,"Y") -> 50
A10: Id1005 | B10: 1966 | C10: Aug | D10: 6 | E10: 0 | F10: 11165.42 | G10: tier - 3 | H10: tier - 1 | I10: R1016 | J10: =TEXT(DATE(B10,MONTH(1&C10),D10),"dd-mm-yyyy") -> 06-08-1966 | K10: 45085 | L10: =DATEDIF(J10,K10,"Y") -> 56
A11: Id1006 | B11: 1969 | C11: Jun | D11: 25 | E11: 2 | F11: 11163.57 | G11: tier - 3 | H11: tier - 2 | I11: R1011 | J11: =TEXT(DATE(B11,MONTH(1&C11),D11),"dd-mm-yyyy") -> 25-06-1969 | K11: 45085 | L11: =DATEDIF(J11,K11,"Y") -> 53
A12: Id1007 | B12: 1969 | C12: Nov | D12: 30 | E12: 2 | F12: 11150.78 | G12: tier - 3 | H12: tier - 2 | I12: R1011 | J12: =TEXT(DATE(B12,MONTH(1&C12),D12),"dd-mm-yyyy") -> 30-11-1969 | K12: 45085 | L12: =DATEDIF(J12,K12,"Y") -> 53
A13: Id1008 | B13: 1980 | C13: Aug | D13: 20 | E13: 2 | F13: 11103.33 | G13: tier - 3 | H13: tier - 1 | I13: R1021 | J13: =TEXT(DATE(B13,MONTH(1&C13),D13),"dd-mm-yyyy") -> 20-08-1980 | K13: 45085 | L13: =DATEDIF(J13,K13,"Y") -> 42
... A2344: Unknown | B2344: 1991 | C2344: Nov | D2344: 22 | E2344: 2 | F2344: 38711 | G2344: tier - 1 | H2344: tier - 3 | I2344: R1011 | J2344: =TEXT(DATE(B2344,MONTH(1&C2344),D2344),"dd-mm-yyyy") -> 22-11-1991 | K2344: 45085 | L2344: =DATEDIF(J2344,K2344,"Y") -> 31

Sheet Pivot table
A3: Row Labels | B3: Count of Smoker | G3: Row Labels | H3: Average of HBA1C | I3: Average of BMI
A4: No | B4: 178 | G4: 18 | H4: 5.3585714 | I4: 36.315357
A5: Yes | B5: 33 | G5: 19 | H5: 5.2833333 | I5: 33.353889
A6: Grand Total | B6: 211 | G6: 20 | H6: 8.66 | I6: 31.94375
G7: 21 | H7: 4.5 | I7: 34.6
G8: 22 | H8: 5.4128571 | I8: 36.091429
A9: Average of HBA1C | B9: Column Labels | G9: 23 | H9: 5.504 | I9: 39.056
A10: Row Labels | B10: 0 | C10: 1 | D10: 2 | E10: Grand Total | G10: 25 | H10: 5.2383333 | I10: 35.7425
A11: Without Transplant | B11: 6.9570297 | C11: 5.7195312 | D11: 7.2492 | E11: 6.5786316 | G11: 26 | H11: 5.1875 | I11: 37.07875
A12: with Transplant | C12: 5.3544444 | D12: 5.0433333 | E12: 5.31 | G12: 27 | H12: 5.005 | I12: 35.095
A13: Grand Total | B13: 6.9570297 | C13: 5.6393902 | D13: 7.0128571 | E13: 6.4523697 | G13: 28 | H13: 4.7666667 | I13: 37.145
A14: Sum of Charges | B14: Column Labels | G14: 29 | H14: 5.0614286 | I14: 38.349286 | J14: a
A15: Row Labels | B15: Obesity | C15: Grand Total | G15: 30 | H15: 4.842 | I15: 41.436
A16: Prediabetes | B16: 3472070.9 | C16: 3472070.9 | G16: 31 | H16: 5.495 | I16: 38.1275
A17: Grand Total | B17: 3472070.9 | C17: 3472070.9 | G17: 32 | H17: 5.3757143 | I17: 41.257143
G18: 33 | H18: 5.0728571 | I18: 39.241429
G19: 34 | H19: 5.426 | I19: 37.435
G20: 35 | H20: 4.9766667 | I20: 37.503333
G21: 36 | H21: 7.73 | I21: 31.27
A22: Row Labels | B22: Average of Charges | C22: Count of State ID | G22: 37 | H22: 5.8385714 | I22: 35.757857
A23: tier - 1 | B23: 36120.304 | C23: 39 | G23: 38 | H23: 5.515 | I23: 38.155
A24: tier - 2 | B24: 13394.144 | C24: 118 | G24: 39 | H24: 5.82 | I24: 35.3
A25: tier - 3 | B25: 8942.0365 | C25: 54 | G25: 40 | H25: 4.8525 | I25: 38.25875
A26: Grand Total | B26: 16455.312 | C26: 211 | G26: 41 | H26: 8.998 | I26: 33.629
G27: 42 | H27: 5.6866667 | I27: 36.891667
G28: 43 | H28: 5.2516667 | I28: 33.13
A29: Row Labels | B29: Count of Charges | G29: 44 | H29: 9.168 | I29: 33.711
A30: 18 | B30: 14 | G30: 45 | H30: 5.4375 | I30: 34.43375
A31: 19 | B31: 9 | G31: 46 | H31: 5.82 | I31: 34.45
A32: 20 | B32: 4 | G32: 47 | H32: 10.4475 | I32: 42.3175
A33: 21 | B33: 1 | G33: 48 | H33: 9.6616667 | I33: 36.685
A34: 22 | B34: 7 | G34: 49 | H34: 9.786 | I34: 39.838
A35: 23 | B35: 5 | G35: 50 | H35: 5.3966667 | I35: 35.471667
A36: 25 | B36: 6 | G36: 51 | H36: 9.34 | I36: 36.192143
A37: 26 | B37: 4 | G37: 52 | H37: 8.626 | I37: 42.061
A38: 27 | B38: 6 | G38: 53 | H38: 5.02 | I38: 36.021667
A39: 28 | B39: 6 | G39: 54 | H39: 9.1075 | I39: 41.105
A40: 29 | B40: 7 | G40: 55 | H40: 10.33 | I40: 36.08
A41: 30 | B41: 5 | G41: 56 | H41: 4.8475 | I41: 39.81
... A48: 37 | B48: 7 | G48: 63 | H48: 6.235 | I48: 36.025
...

Sheet Dashboard
J2: Healthcare Data Analytics

Sheet Health Care
A1: Customer Id | B1: First Name | C1: BMI | D1: HBA1C | E1: Heart Issue | F1: Any Transplants | G1: Cancer History | H1: Number Of Major Surgeries | I1: Smoker | J1: Weight Status | K1: Diabetes Status | L1: Date Of Birth | M1: Charges | N1: Hospital Tier | O1: City Tier | P1: State ID | Q1: Age
A2: Id1 | B2: =VLOOKUP($A2,'Customer Names'!$A$2:$E$2336,4,0) -> Kelly | C2: =VLOOKUP($A2,'Medical Examination'!$A$2:$J$2336,2,0) -> 47.41 | D2: =VLOOKUP($A2,'Medical Examination'!$A$2:$J$2336,3,0) -> 7.47 | E2: =VLOOKUP($A2,'Medical Examination'!$A$2:$J$2336,4,0) -> No | F2: =VLOOKUP($A2,'Medical Examination'!$A$2:$J$2336,5,0) -> No | G2: =VLOOKUP($A2,'Medical Examination'!$A$2:$J$2336,6,0) -> No | H2: =VLOOKUP($A2,'Medical Examination'!$A$2:$J$2336,7,0) -> 0 | I2: =VLOOKUP($A2,'Medical Examination'!$A$2:$J$2336,8,0) -> Smoker | J2: =VLOOKUP($A2,'Medical Examination'!$A$2:$J$2336,9,0) -> Obesity | K2: =VLOOKUP($A2,'Medical Examination'!$A$2:$J$2336,10,0) -> Prediabetes | L2: =VLOOKUP($A2,'Hospitalsation Details'!$A$2:$L$2344,10,0) -> 12-10-1968 | M2: =VLOOKUP($A2,'Hospitalsation Details'!$A$2:$L$2344,6,0) -> 63770.43 | N2: =VLOOKUP($A2,'Hospitalsation Details'!$A$2:$L$2344,7,0) -> tier - 1 | O2: =VLOOKUP($A2,'Hospitalsation Details'!$A$2:$L$2344,8,0) -> tier - 3 | P2: =VLOOKUP($A2,'Hospitalsation Details'!$A$2:$L$2344,9,0) -> R1013 | Q2: =VLOOKUP($A2,'Hospitalsation Details'!$A$2:$L$2344,12,0) -> 54
A3: Id2 | B3: =VLOOKUP($A3,'Customer Names'!$A$2:$E$2336,4,0) -> Matthew D | C3: =VLOOKUP($A3,'Medical Examination'!$A$2:$J$2336,2,0) -> 30.36 | D3: =VLOOKUP($A3,'Medical Examination'!$A$2:$J$2336,3,0) -> 5.77 | E3: =VLOOKUP($A3,'Medical Examination'!$A$2:$J$2336,4,0) -> No | F3: =VLOOKUP($A3,'Medical Examination'!$A$2:$J$2336,5,0) -> No | G3: =VLOOKUP($A3,'Medical Examination'!$A$2:$J$2336,6,0) -> No | H3: =VLOOKUP($A3,'Medical Examination'!$A$2:$J$2336,7,0) -> 0 | I3: =VLOOKUP($A3,'Medical Examination'!$A$2:$J$2336,8,0) -> Smoker | J3: =VLOOKUP($A3,'Medical Examination'!$A$2:$J$2336,9,0) -> Obesity | K3: =VLOOKUP($A3,'Medical Examination'!$A$2:$J$2336,10,0) -> Diabetes | L3: =VLOOKUP($A3,'Hospitalsation Details'!$A$2:$L$2344,10,0) -> 08-06-1977 | M3: =VLOOKUP($A3,'Hospitalsation Details'!$A$2:$L$2344,6,0) -> 62592.87 | N3: =VLOOKUP($A3,'Hospitalsation Details'!$A$2:$L$2344,7,0) -> tier - 2 | O3: =VLOOKUP($A3,'Hospitalsation Details'!$A$2:$L$2344,8,0) -> tier - 3 | P3: =VLOOKUP($A3,'Hospitalsation Details'!$A$2:$L$2344,9,0) -> R1013 | Q3: =VLOOKUP($A3,'Hospitalsation Details'!$A$2:$L$2344,12,0) -> 46
A4: Id3 | B4: =VLOOKUP($A4,'Customer Names'!$A$2:$E$2336,4,0) -> Phil | C4: =VLOOKUP($A4,'Medical Examination'!$A$2:$J$2336,2,0) -> 34.485 | D4: =VLOOKUP($A4,'Medical Examination'!$A$2:$J$2336,3,0) -> 11.87 | E4: =VLOOKUP($A4,'Medical Examination'!$A$2:$J$2336,4,0) -> Yes | F4: =VLOOKUP($A4,'Medical Examination'!$A$2:$J$2336,5,0) -> No | G4: =VLOOKUP($A4,'Medical Examination'!$A$2:$J$2336,6,0) -> No | H4: =VLOOKUP($A4,'Medical Examination'!$A$2:$J$2336,7,0) -> 2 | I4: =VLOOKUP($A4,'Medical Examination'!$A$2:$J$2336,8,0) -> Smoker | J4: =VLOOKUP($A4,'Medical Examination'!$A$2:$J$2336,9,0) -> Obesity | K4: =VLOOKUP($A4,'Medical Examination'!$A$2:$J$2336,10,0) -> Prediabetes | L4: =VLOOKUP($A4,'Hospitalsation Details'!$A$2:$L$2344,10,0) -> 11-09-1970 | M4: =VLOOKUP($A4,'Hospitalsation Details'!$A$2:$L$2344,6,0) -> 60021.4 | N4: =VLOOKUP($A4,'Hospitalsation Details'!$A$2:$L$2344,7,0) -> tier - 1 | O4: =VLOOKUP($A4,'Hospitalsation Details'!$A$2:$L$2344,8,0) -> tier - 1 | P4: =VLOOKUP($A4,'Hospitalsation Details'!$A$2:$L$2344,9,0) -> R1012 | Q4: =VLOOKUP($A4,'Hospitalsation Details'!$A$2:$L$2344,12,0) -> 52
A5: Id4 | B5: =VLOOKUP($A5,'Customer Names'!$A$2:$E$2336,4,0) -> Kelsey | C5: =VLOOKUP($A5,'Medical Examination'!$A$2:$J$2336,2,0) -> 38.095 | D5: =VLOOKUP($A5,'Medical Examination'!$A$2:$J$2336,3,0) -> 6.05 | E5: =VLOOKUP($A5,'Medical Examination'!$A$2:$J$2336,4,0) -> No | F5: =VLOOKUP($A5,'Medical Examination'!$A$2:$J$2336,5,0) -> No | G5: =VLOOKUP($A5,'Medical Examination'!$A$2:$J$2336,6,0) -> No | H5: =VLOOKUP($A5,'Medical Examination'!$A$2:$J$2336,7,0) -> 0 | I5: =VLOOKUP($A5,'Medical Examination'!$A$2:$J$2336,8,0) -> Smoker | J5: =VLOOKUP($A5,'Medical Examination'!$A$2:$J$2336,9,0) -> Obesity | K5: =VLOOKUP($A5,'Medical Examination'!$A$2:$J$2336,10,0) -> Normal | L5: =VLOOKUP($A5,'Hospitalsation Details'!$A$2:$L$2344,10,0) -> 06-06-1991 | M5: =VLOOKUP($A5,'Hospitalsation Details'!$A$2:$L$2344,6,0) -> 58571.07 | N5: =VLOOKUP($A5,'Hospitalsation Details'!$A$2:$L$2344,7,0) -> tier - 1 | O5: =VLOOKUP($A5,'Hospitalsation Details'!$A$2:$L$2344,8,0) -> tier - 3 | P5: =VLOOKUP($A5,'Hospitalsation Details'!$A$2:$L$2344,9,0) -> R1024 | Q5: =VLOOKUP($A5,'Hospitalsation Details'!$A$2:$L$2344,12,0) -> 32
A6: Id5 | B6: =VLOOKUP($A6,'Customer Names'!$A$2:$E$2336,4,0) -> Kristyn | C6: =VLOOKUP($A6,'Medical Examination'!$A$2:$J$2336,2,0) -> 35.53 | D6: =VLOOKUP($A6,'Medical Examination'!$A$2:$J$2336,3,0) -> 5.45 | E6: =VLOOKUP($A6,'Medical Examination'!$A$2:$J$2336,4,0) -> No | F6: =VLOOKUP($A6,'Medical Examination'!$A$2:$J$2336,5,0) -> No | G6: =VLOOKUP($A6,'Medical Examination'!$A$2:$J$2336,6,0) -> No | H6: =VLOOKUP($A6,'Medical Examination'!$A$2:$J$2336,7,0) -> 0 | I6: =VLOOKUP($A6,'Medical Examination'!$A$2:$J$2336,8,0) -> Smoker | J6: =VLOOKUP($A6,'Medical Examination'!$A$2:$J$2336,9,0) -> Obesity | K6: =VLOOKUP($A6,'Medical Examination'!$A$2:$J$2336,10,0) -> Diabetes | L6: =VLOOKUP($A6,'Hospitalsation Details'!$A$2:$L$2344,10,0) -> 19-06-1989 | M6: =VLOOKUP($A6,'Hospitalsation Details'!$A$2:$L$2344,6,0) -> 55135.4 | N6: =VLOOKUP($A6,'Hospitalsation Details'!$A$2:$L$2344,7,0) -> tier - 1 | O6: =VLOOKUP($A6,'Hospitalsation Details'!$A$2:$L$2344,8,0) -> tier - 2 | P6: =VLOOKUP($A6,'Hospitalsation Details'!$A$2:$L$2344,9,0) -> R1012 | Q6: =VLOOKUP($A6,'Hospitalsation Details'!$A$2:$L$2344,12,0) -> 33
A7: Id6 | B7: =VLOOKUP($A7,'Customer Names'!$A$2:$E$2336,4,0) -> Russell B | C7: =VLOOKUP($A7,'Medical Examination'!$A$2:$J$2336,2,0) -> 32.8 | D7: =VLOOKUP($A7,'Medical Examination'!$A$2:$J$2336,3,0) -> 6.59 | E7: =VLOOKUP($A7,'Medical Examination'!$A$2:$J$2336,4,0) -> No | F7: =VLOOKUP($A7,'Medical Examination'!$A$2:$J$2336,5,0) -> No | G7: =VLOOKUP($A7,'Medical Examination'!$A$2:$J$2336,6,0) -> No | H7: =VLOOKUP($A7,'Medical Examination'!$A$2:$J$2336,7,0) -> 0 | I7: =VLOOKUP($A7,'Medical Examination'!$A$2:$J$2336,8,0) -> Smoker | J7: =VLOOKUP($A7,'Medical Examination'!$A$2:$J$2336,9,0) -> Obesity | K7: =VLOOKUP($A7,'Medical Examination'!$A$2:$J$2336,10,0) -> Prediabetes | L7: =VLOOKUP($A7,'Hospitalsation Details'!$A$2:$L$2344,10,0) -> 04-08-1962 | M7: =VLOOKUP($A7,'Hospitalsation Details'!$A$2:$L$2344,6,0) -> 52590.83 | N7: =VLOOKUP($A7,'Hospitalsation Details'!$A$2:$L$2344,7,0) -> tier - 1 | O7: =VLOOKUP($A7,'Hospitalsation Details'!$A$2:$L$2344,8,0) -> tier - 3 | P7: =VLOOKUP($A7,'Hospitalsation Details'!$A$2:$L$2344,9,0) -> R1011 | Q7: =VLOOKUP($A7,'Hospitalsation Details'!$A$2:$L$2344,12,0) -> 60
A8: Id7 | B8: =VLOOKUP($A8,'Customer Names'!$A$2:$E$2336,4,0) -> Scott | C8: =VLOOKUP($A8,'Medical Examination'!$A$2:$J$2336,2,0) -> 36.4 | D8: =VLOOKUP($A8,'Medical Examination'!$A$2:$J$2336,3,0) -> 6.07 | E8: =VLOOKUP($A8,'Medical Examination'!$A$2:$J$2336,4,0) -> No | F8: =VLOOKUP($A8,'Medical Examination'!$A$2:$J$2336,5,0) -> No | G8: =VLOOKUP($A8,'Medical Examination'!$A$2:$J$2336,6,0) -> No | H8: =VLOOKUP($A8,'Medical Examination'!$A$2:$J$2336,7,0) -> 0 | I8: =VLOOKUP($A8,'Medical Examination'!$A$2:$J$2336,8,0) -> Smoker | J8: =VLOOKUP($A8,'Medical Examination'!$A$2:$J$2336,9,0) -> Obesity | K8: =VLOOKUP($A8,'Medical Examination'!$A$2:$J$2336,10,0) -> Diabetes | L8: =VLOOKUP($A8,'Hospitalsation Details'!$A$2:$L$2344,10,0) -> 27-10-1994 | M8: =VLOOKUP($A8,'Hospitalsation Details'!$A$2:$L$2344,6,0) -> 51194.56 | N8: =VLOOKUP($A8,'Hospitalsation Details'!$A$2:$L$2344,7,0) -> tier - 1 | O8: =VLOOKUP($A8,'Hospitalsation Details'!$A$2:$L$2344,8,0) -> tier - 3 | P8: =VLOOKUP($A8,'Hospitalsation Details'!$A$2:$L$2344,9,0) -> R1011 | Q8: =VLOOKUP($A8,'Hospitalsation Details'!$A$2:$L$2344,12,0) -> 28
A9: Id8 | B9: =VLOOKUP($A9,'Customer Names'!$A$2:$E$2336,4,0) -> Stephen | C9: =VLOOKUP($A9,'Medical Examination'!$A$2:$J$2336,2,0) -> 36.96 | D9: =VLOOKUP($A9,'Medical Examination'!$A$2:$J$2336,3,0) -> 7.93 | E9: =VLOOKUP($A9,'Medical Examination'!$A$2:$J$2336,4,0) -> No | F9: =VLOOKUP($A9,'Medical Examination'!$A$2:$J$2336,5,0) -> No | G9: =VLOOKUP($A9,'Medical Examination'!$A$2:$J$2336,6,0) -> No | H9: =VLOOKUP($A9,'Medical Examination'!$A$2:$J$2336,7,0) -> 3 | I9: =VLOOKUP($A9,'Medical Examination'!$A$2:$J$2336,8,0) -> Smoker | J9: =VLOOKUP($A9,'Medical Examination'!$A$2:$J$2336,9,0) -> Obesity | K9: =VLOOKUP($A9,'Medical Examination'!$A$2:$J$2336,10,0) -> Diabetes | L9: =VLOOKUP($A9,'Hospitalsation Details'!$A$2:$L$2344,10,0) -> 27-06-1958 | M9: =VLOOKUP($A9,'Hospitalsation Details'!$A$2:$L$2344,6,0) -> 49577.66 | N9: =VLOOKUP($A9,'Hospitalsation Details'!$A$2:$L$2344,7,0) -> tier - 2 | O9: =VLOOKUP($A9,'Hospitalsation Details'!$A$2:$L$2344,8,0) -> tier - 2 | P9: =VLOOKUP($A9,'Hospitalsation Details'!$A$2:$L$2344,9,0) -> R1013 | Q9: =VLOOKUP($A9,'Hospitalsation Details'!$A$2:$L$2344,12,0) -> 64
A10: Id9 | B10: =VLOOKUP($A10,'Customer Names'!$A$2:$E$2336,4,0) -> Patrick R | C10: =VLOOKUP($A10,'Medical Examination'!$A$2:$J$2336,2,0) -> 41.14 | D10: =VLOOKUP($A10,'Medical Examination'!$A$2:$J$2336,3,0) -> 9.58 | E10: =VLOOKUP($A10,'Medical Examination'!$A$2:$J$2336,4,0) -> Yes | F10: =VLOOKUP($A10,'Medical Examination'!$A$2:$J$2336,5,0) -> No | G10: =VLOOKUP($A10,'Medical Examination'!$A$2:$J$2336,6,0) -> Yes | H10: =VLOOKUP($A10,'Medical Examination'!$A$2:$J$2336,7,0) -> 1 | I10: =VLOOKUP($A10,'Medical Examination'!$A$2:$J$2336,8,0) -> Smoker | J10: =VLOOKUP($A10,'Medical Examination'!$A$2:$J$2336,9,0) -> Obesity | K10: =VLOOKUP($A10,'Medical Examination'!$A$2:$J$2336,10,0) -> Diabetes | L10: =VLOOKUP($A10,'Hospitalsation Details'!$A$2:$L$2344,10,0) -> 04-09-1963 | M10: =VLOOKUP($A10,'Hospitalsation Details'!$A$2:$L$2344,6,0) -> 48970.25 | N10: =VLOOKUP($A10,'Hospitalsation Details'!$A$2:$L$2344,7,0) -> tier - 1 | O10: =VLOOKUP($A10,'Hospitalsation Details'!$A$2:$L$2344,8,0) -> tier - 2 | P10: =VLOOKUP($A10,'Hospitalsation Details'!$A$2:$L$2344,9,0) -> R1013 | Q10: =VLOOKUP($A10,'Hospitalsation Details'!$A$2:$L$2344,12,0) -> 59
A11: Id10 | B11: =VLOOKUP($A11,'Customer Names'!$A$2:$E$2336,4,0) -> Brooke N | C11: =VLOOKUP($A11,'Medical Examination'!$A$2:$J$2336,2,0) -> 38.06 | D11: =VLOOKUP($A11,'Medical Examination'!$A$2:$J$2336,3,0) -> 10.79 | E11: =VLOOKUP($A11,'Medical Examination'!$A$2:$J$2336,4,0) -> No | F11: =VLOOKUP($A11,'Medical Examination'!$A$2:$J$2336,5,0) -> No | G11: =VLOOKUP($A11,'Medical Examination'!$A$2:$J$2336,6,0) -> No | H11: =VLOOKUP($A11,'Medical Examination'!$A$2:$J$2336,7,0) -> 0 | I11: =VLOOKUP($A11,'Medical Examination'!$A$2:$J$2336,8,0) -> Smoker | J11: =VLOOKUP($A11,'Medical Examination'!$A$2:$J$2336,9,0) -> Obesity | K11: =VLOOKUP($A11,'Medical Examination'!$A$2:$J$2336,10,0) -> Prediabetes | L11: =VLOOKUP($A11,'Hospitalsation Details'!$A$2:$L$2344,10,0) -> 29-12-1978 | M11: =VLOOKUP($A11,'Hospitalsation Details'!$A$2:$L$2344,6,0) -> 48885.14 | N11: =VLOOKUP($A11,'Hospitalsation Details'!$A$2:$L$2344,7,0) -> tier - 1 | O11: =VLOOKUP($A11,'Hospitalsation Details'!$A$2:$L$2344,8,0) -> tier - 2 | P11: =VLOOKUP($A11,'Hospitalsation Details'!$A$2:$L$2344,9,0) -> R1013 | Q11: =VLOOKUP($A11,'Hospitalsation Details'!$A$2:$L$2344,12,0) -> 44
A12: Id11 | B12: =VLOOKUP($A12,'Customer Names'!$A$2:$E$2336,4,0) -> Paola Andrea | C12: =VLOOKUP($A12,'Medical Examination'!$A$2:$J$2336,2,0) -> 37.7 | D12: =VLOOKUP($A12,'Medical Examination'!$A$2:$J$2336,3,0) -> 5.96 | E12: =VLOOKUP($A12,'Medical Examination'!$A$2:$J$2336,4,0) -> Yes | F12: =VLOOKUP($A12,'Medical Examination'!$A$2:$J$2336,5,0) -> No | G12: =VLOOKUP($A12,'Medical Examination'!$A$2:$J$2336,6,0) -> No | H12: =VLOOKUP($A12,'Medical Examination'!$A$2:$J$2336,7,0) -> 2 | I12: =VLOOKUP($A12,'Medical Examination'!$A$2:$J$2336,8,0) -> Smoker | J12: =VLOOKUP($A12,'Medical Examination'!$A$2:$J$2336,9,0) -> Obesity | K12: =VLOOKUP($A12,'Medical Examination'!$A$2:$J$2336,10,0) -> Diabetes | L12: =VLOOKUP($A12,'Hospitalsation Details'!$A$2:$L$2344,10,0) -> 22-07-1959 | M12: =VLOOKUP($A12,'Hospitalsation Details'!$A$2:$L$2344,6,0) -> 48824.45 | N12: =VLOOKUP($A12,'Hospitalsation Details'!$A$2:$L$2344,7,0) -> tier - 2 | O12: =VLOOKUP($A12,'Hospitalsation Details'!$A$2:$L$2344,8,0) -> tier - 1 | P12: =VLOOKUP($A12,'Hospitalsation Details'!$A$2:$L$2344,9,0) -> R1011 | Q12: =VLOOKUP($A12,'Hospitalsation Details'!$A$2:$L$2344,12,0) -> 63
A13: Id12 | B13: =VLOOKUP($A13,'Customer Names'!$A$2:$E$2336,4,0) -> David | C13: =VLOOKUP($A13,'Medical Examination'!$A$2:$J$2336,2,0) -> 42.13 | D13: =VLOOKUP($A13,'Medical Examination'!$A$2:$J$2336,3,0) -> 11.9 | E13: =VLOOKUP($A13,'Medical Examination'!$A$2:$J$2336,4,0) -> No | F13: =VLOOKUP($A13,'Medical Examination'!$A$2:$J$2336,5,0) -> No | G13: =VLOOKUP($A13,'Medical Examination'!$A$2:$J$2336,6,0) -> No | H13: =VLOOKUP($A13,'Medical Examination'!$A$2:$J$2336,7,0) -> 0 | I13: =VLOOKUP($A13,'Medical Examination'!$A$2:$J$2336,8,0) -> Smoker | J13: =VLOOKUP($A13,'Medical Examination'!$A$2:$J$2336,9,0) -> Obesity | K13: =VLOOKUP($A13,'Medical Examination'!$A$2:$J$2336,10,0) -> Diabetes | L13: =VLOOKUP($A13,'Hospitalsation Details'!$A$2:$L$2344,10,0) -> 27-10-1965 | M13: =VLOOKUP($A13,'Hospitalsation Details'!$A$2:$L$2344,6,0) -> 48675.52 | N13: =VLOOKUP($A13,'Hospitalsation Details'!$A$2:$L$2344,7,0) -> tier - 1 | O13: =VLOOKUP($A13,'Hospitalsation Details'!$A$2:$L$2344,8,0) -> tier - 2 | P13: =VLOOKUP($A13,'Hospitalsation Details'!$A$2:$L$2344,9,0) -> R1013 | Q13: =VLOOKUP($A13,'Hospitalsation Details'!$A$2:$L$2344,12,0) -> 57
... A2336: Id2335 | B2336: =VLOOKUP($A2336,'Customer Names'!$A$2:$E$2336,4,0) -> Aaron K | C2336: =VLOOKUP($A2336,'Medical Examination'!$A$2:$J$2336,2,0) -> 17.58 | D2336: =VLOOKUP($A2336,'Medical Examination'!$A$2:$J$2336,3,0) -> 4.51 | E2336: =VLOOKUP($A2336,'Medical Examination'!$A$2:$J$2336,4,0) -> No | F2336: =VLOOKUP($A2336,'Medical Examination'!$A$2:$J$2336,5,0) -> No | G2336: =VLOOKUP($A2336,'Medical Examination'!$A$2:$J$2336,6,0) -> No | H2336: =VLOOKUP($A2336,'Medical Examination'!$A$2:$J$2336,7,0) -> 1 | I2336: =VLOOKUP($A2336,'Medical Examination'!$A$2:$J$2336,8,0) -> Non Smoker | J2336: =VLOOKUP($A2336,'Medical Examination'!$A$2:$J$2336,9,0) -> Under Weight | K2336: =VLOOKUP($A2336,'Medical Examination'!$A$2:$J$2336,10,0) -> Normal | L2336: =VLOOKUP($A2336,'Hospitalsation Details'!$A$2:$L$2344,10,0) -> 09-07-1992 | M2336: =VLOOKUP($A2336,'Hospitalsation Details'!$A$2:$L$2344,6,0) -> 563.84 | N2336: =VLOOKUP($A2336,'Hospitalsation Details'!$A$2:$L$2344,7,0) -> tier - 2 | O2336: =VLOOKUP($A2336,'Hospitalsation Details'!$A$2:$L$2344,8,0) -> tier - 3 | P2336: =VLOOKUP($A2336,'Hospitalsation Details'!$A$2:$L$2344,9,0) -> R1013 | Q2336: =VLOOKUP($A2336,'Hospitalsation Details'!$A$2:$L$2344,12,0) -> 30
